<mujoco model="CC1">
  <default>
    <default class="robot">
      <default class="motor">
        <joint />
        <motor />
      </default>
      <default class="visual">
        <geom material="visualgeom" contype="0" conaffinity="0" group="2" />
      </default>
      <default class="collision">
        <geom material="collision_material" condim="3" contype="0" conaffinity="1" group="1" solref="0.005 1" friction="1 0.01 0.01" />
        <equality solimp="0.99 0.999 1e-05" solref="0.005 1" />
      </default>
    </default>
  </default>
  <compiler angle="radian" autolimits="true"/>
  <asset>
    <material name="default_material" rgba="0.7 0.7 0.7 1" />
    <material name="collision_material" rgba="0.0 0.4 0.8 0.2" />
    <texture type="2d" name="checker" builtin="checker" rgb1="0.2 0.3 0.4" rgb2="0.9 0.9 0.9" width="500" height="500"/>
    <material name="checker_mat" texture="checker" specular="1" shininess="1" texrepeat="15 15"/>
    <mesh name="torso.STL"               file="../meshes/robot_dog_simplified.STL" />
    <mesh name="fl_hip.STL"              file="../meshes/fl_hip.STL" />
    <mesh name="fl_thigh.STL"            file="../meshes/fl_thigh.STL" />
    <mesh name="fl_shank.STL"            file="../meshes/fl_shank.STL" />
    <mesh name="fr_hip.STL"              file="../meshes/fr_hip.STL" />
    <mesh name="fr_thigh.STL"            file="../meshes/fr_thigh.STL" />
    <mesh name="fr_shank.STL"            file="../meshes/fr_shank.STL" />
    <mesh name="hl_hip.STL"              file="../meshes/hl_hip.STL" />
    <mesh name="hl_thigh.STL"            file="../meshes/hl_thigh.STL" />
    <mesh name="hl_shank.STL"            file="../meshes/hl_shank.STL" />
    <mesh name="hr_hip.STL"              file="../meshes/hr_hip.STL" />
    <mesh name="hr_thigh.STL"            file="../meshes/hr_thigh.STL" />
    <mesh name="hr_shank.STL"            file="../meshes/hr_shank.STL" />
  </asset>
  <worldbody>
    <geom name="floor" type="plane" size="10 10 0.1" pos="0 0 0" material="checker_mat"/>
    <light directional="true" pos="-0.5 0.5 3" dir="0 0 -1"/>
    <body name="TORSO" pos="0 0 1." quat="1 0 0 0" childclass="robot">
      <freejoint name="floating_base" />
      <site name="imu_site" pos="0 0 0" size="0.005" rgba="1 0 0 1"/>
      <inertial pos="0.054652 -0.000292 0.045209" mass="7.794"
                fullinertia="0.015847 0.021604 0.026694 -9.3712E-05 -0.0015126 4.6335E-05"/>
      <geom name="TORSO_collision" pos="0 0 0" quat="1 0 0 0" type="mesh" mesh="torso.STL" class="collision" />
      <geom name="TORSO_visual"    pos="0 0 0" quat="1 0 0 0" material="" type="mesh" mesh="torso.STL" class="visual" />

      <!-- FL leg -->
      <body name="FL_HIP" pos="0.16089 0.0767 0" quat="1 0 0 0">
        <joint name="FL_HipX_joint" type="hinge" ref="0.0" class="motor"
               range="-0.698 0.5236" axis="-1 0 0" damping="0.03" frictionloss="0.01"/>
        <inertial pos="-0.00242 -0.02418 0.00018" mass="0.668"
                  fullinertia="8.6098E-05 0.0001737 0.00010131 -6.2639E-06 4.2573E-08 5.8218E-08"/>
        <geom name="FL_HIP_collision" pos="0 0 0" quat="1 0 0 0" type="mesh" mesh="fl_hip.STL" class="collision" />
        <geom name="FL_HIP_visual"    pos="0 0 0" quat="1 0 0 0" material="" type="mesh" mesh="fl_hip.STL" class="visual" />
        <body name="FL_THIGH" pos="0 0.0855 0" quat="1 0 0 0">
          <joint name="FL_HipY_joint" type="hinge" ref="0.0" class="motor"
                 range="-2.792 1.57" axis="0 -1 0" damping="0.03" frictionloss="0.01"/>
          <inertial pos="-0.0034 -0.02856 -0.0333" mass="1.291"
                    fullinertia="0.0022032 0.0025033 0.00036638 2.0678E-08 -0.00011021 -2.4395E-05"/>
          <geom name="FL_THIGH_collision" pos="0 0 0" quat="1 0 0 0" type="mesh" mesh="fl_thigh.STL" class="collision" />
          <geom name="FL_THIGH_visual"    pos="0 0 0" quat="1 0 0 0" material="" type="mesh" mesh="fl_thigh.STL" class="visual" />
          <body name="FL_SHANK" pos="0 0 -0.2" quat="1 0 0 0">
            <joint name="FL_Knee_joint" type="hinge" ref="0.0" class="motor"
                   range="0.5236 2.7225" axis="0 -1 0" damping="0.03" frictionloss="0.01"/>
            <inertial pos="0.00356 0.0006726 -0.13678" mass="0.18211"
                      fullinertia="0.00075917 0.00078539 3.9968E-05 -7.684E-07 3.526E-05 1.8758E-06"/>
            <geom name="FL_SHANK_collision" pos="0 0 0" quat="1 0 0 0" type="mesh" mesh="fl_shank.STL" class="collision" />
            <geom name="FL_SHANK_visual"    pos="0 0 0" quat="1 0 0 0" material="" type="mesh" mesh="fl_shank.STL" class="visual" />
            <body name="FL_FOOT" pos="0 0 -0.22" quat="1 0 0 0">
              <inertial pos="0 0 0" mass="0.06" diaginertia="1E-12 1E-12 1E-12"/>
              <geom name="FL_FOOT_collision" pos="0 0 0" quat="0.7071067811882787 0.7071067811848163 0 0" type="sphere" size="0.03" class="collision" />
              <geom name="FL_FOOT_visual"    pos="0 0 0" quat="1 0 0 0" material="" type="sphere" size="0.032" class="visual" />
            </body>
          </body>
        </body>
      </body>

      <!-- FR leg -->
      <body name="FR_HIP" pos="0.16089 -0.0767 0" quat="1 0 0 0">
        <joint name="FR_HipX_joint" type="hinge" ref="0.0" class="motor"
               range="-0.5236 0.698" axis="-1 0 0" damping="0.03" frictionloss="0.01"/>
        <inertial pos="-0.00242 0.02418 0.00018" mass="0.668"
                  fullinertia="8.6098E-05 0.0001737 0.00010131 6.3852E-06 -4.2573E-08 -6.2018E-08"/>
        <geom name="FR_HIP_collision" pos="0 0 0" quat="1 0 0 0" type="mesh" mesh="fr_hip.STL" class="collision" />
        <geom name="FR_HIP_visual"    pos="0 0 0" quat="1 0 0 0" material="" type="mesh" mesh="fr_hip.STL" class="visual" />
        <body name="FR_THIGH" pos="0 -0.085493 0" quat="1 0 0 0">
          <joint name="FR_HipY_joint" type="hinge" ref="0.0" class="motor"
                 range="-2.792 1.57" axis="0 -1 0" damping="0.03" frictionloss="0.01"/>
          <inertial pos="-0.00464 0.02702 -0.03438" mass="1.297"
                    fullinertia="0.0022029 0.002503 0.00036636 3.3146E-07 -0.00011149 2.4433E-05"/>
          <geom name="FR_THIGH_collision" pos="0 0 0" quat="1 0 0 0" type="mesh" mesh="fr_thigh.STL" class="collision" />
          <geom name="FR_THIGH_visual"    pos="0 0 0" quat="1 0 0 0" material="" type="mesh" mesh="fr_thigh.STL" class="visual" />
          <body name="FR_SHANK" pos="0 0 -0.2" quat="1 0 0 0">
            <joint name="FR_Knee_joint" type="hinge" ref="0.0" class="motor"
                   range="0.5236 2.7225" axis="0 -1 0" damping="0.03" frictionloss="0.01"/>
            <inertial pos="0.0035662 -0.00062306 -0.13683" mass="0.18206"
                      fullinertia="0.0007587 0.0007849 3.9944E-05 7.7196E-07 3.5137E-05 -1.8954E-06"/>
            <geom name="FR_SHANK_collision" pos="0 0 0" quat="1 0 0 0" type="mesh" mesh="fr_shank.STL" class="collision" />
            <geom name="FR_SHANK_visual"    pos="0 0 0" quat="1 0 0 0" material="" type="mesh" mesh="fr_shank.STL" class="visual" />
            <body name="FR_FOOT" pos="0 0 -0.22" quat="1 0 0 0">
              <inertial pos="0 0 0" mass="0.06" diaginertia="1E-12 1E-12 1E-12"/>
              <geom name="FR_FOOT_collision" pos="0 0 0" quat="0.7071067811882787 0.7071067811848163 0 0" type="sphere" size="0.03" class="collision" />
              <geom name="FR_FOOT_visual"    pos="0 0 0" quat="1 0 0 0" material="" type="sphere" size="0.032" class="visual" />
            </body>
          </body>
        </body>
      </body>

      <!-- HL leg -->
      <body name="HL_HIP" pos="-0.16088 0.076239 0.0032508" quat="1 0 0 0">
        <joint name="HL_HipX_joint" type="hinge" ref="0.0" class="motor"
               range="-0.698 0.5236" axis="-1 0 0" damping="0.03" frictionloss="0.01"/>
        <inertial pos="-0.00242 -0.02418 0.00018" mass="0.668"
                  fullinertia="8.6098E-05 0.0001737 0.00010131 6.3852E-06 4.2573E-08 6.2018E-08"/>
        <geom name="HL_HIP_collision" pos="0 0 0" quat="1 0 0 0" type="mesh" mesh="hl_hip.STL" class="collision" />
        <geom name="HL_HIP_visual"    pos="0 0 0" quat="1 0 0 0" material="" type="mesh" mesh="hl_hip.STL" class="visual" />
        <body name="HL_THIGH" pos="0 0.086286 -0.0032508" quat="1 0 0 0">
          <joint name="HL_HipY_joint" type="hinge" ref="0.0" class="motor"
                 range="-2.792 1.57" axis="0 -1 0" damping="0.03" frictionloss="0.01"/>
          <inertial pos="-0.0034 -0.02856 -0.0333" mass="1.291"
                    fullinertia="0.0022033 0.0025036 0.0003667 -8.9938E-07 -0.00011017 -2.5629E-05"/>
          <geom name="HL_THIGH_collision" pos="0 0 0" quat="1 0 0 0" type="mesh" mesh="hl_thigh.STL" class="collision" />
          <geom name="HL_THIGH_visual"    pos="0 0 0" quat="1 0 0 0" material="" type="mesh" mesh="hl_thigh.STL" class="visual" />
          <body name="HL_SHANK" pos="0 0 -0.2" quat="1 0 0 0">
            <joint name="HL_Knee_joint" type="hinge" ref="0.0" class="motor"
                   range="0.5236 2.7225" axis="0 -1 0" damping="0.03" frictionloss="0.01"/>
            <inertial pos="0.0035588 0.00067259 -0.13678" mass="0.18211"
                      fullinertia="0.00075917 0.00078539 3.9969E-05 -7.6834E-07 3.526E-05 1.8757E-06"/>
            <geom name="HL_SHANK_collision" pos="0 0 0" quat="1 0 0 0" type="mesh" mesh="hl_shank.STL" class="collision" />
            <geom name="HL_SHANK_visual"    pos="0 0 0" quat="1 0 0 0" material="" type="mesh" mesh="hl_shank.STL" class="visual" />
            <body name="HL_FOOT" pos="0 0 -0.22" quat="1 0 0 0">
              <inertial pos="0 0 0" mass="0.06" diaginertia="1E-12 1E-12 1E-12"/>
              <geom name="HL_FOOT_collision" pos="0 0 0" quat="0.7071067811882787 0.7071067811848163 0 0" type="sphere" size="0.03" class="collision" />
              <geom name="HL_FOOT_visual"    pos="0 0 0" quat="1 0 0 0" material="" type="sphere" size="0.032" class="visual" />
            </body>
          </body>
        </body>
      </body>

      <!-- HR leg -->
      <body name="HR_HIP" pos="-0.16088 -0.076306 0.0030093" quat="1 0 0 0">
        <joint name="HR_HipX_joint" type="hinge" ref="0.0" class="motor"
               range="-0.5236 0.698" axis="-1 0 0" damping="0.03" frictionloss="0.01"/>
        <inertial pos="-0.00242 0.02418 0.00018" mass="0.668"
                  fullinertia="8.6098E-05 0.0001737 0.00010131 -6.2639E-06 -4.2573E-08 -5.8218E-08"/>
        <geom name="HR_HIP_collision" pos="0 0 0" quat="1 0 0 0" type="mesh" mesh="hr_hip.STL" class="collision" />
        <geom name="HR_HIP_visual"    pos="0 0 0" quat="1 0 0 0" material="" type="mesh" mesh="hr_hip.STL" class="visual" />
        <body name="HR_THIGH" pos="0 -0.086219 0.0" quat="1 0 0 0">
          <joint name="HR_HipY_joint" type="hinge" ref="0.0" class="motor"
                 range="-2.792 1.57" axis="0 -1 0" damping="0.03" frictionloss="0.01"/>
          <inertial pos="-0.00464 0.02702 -0.03438" mass="1.291"
                    fullinertia="0.0022028 0.002503 0.00036649 4.9374E-07 -0.00010697 2.5638E-05"/>
          <geom name="HR_THIGH_collision" pos="0 0 0" quat="1 0 0 0" type="mesh" mesh="hr_thigh.STL" class="collision" />
          <geom name="HR_THIGH_visual"    pos="0 0 0" quat="1 0 0 0" material="" type="mesh" mesh="hr_thigh.STL" class="visual" />
          <body name="HR_SHANK" pos="0 0 -0.19117" quat="1 0 0 0">
            <joint name="HR_Knee_joint" type="hinge" ref="0.0" class="motor"
                   range="0.5236 2.7225" axis="0 -1 0" damping="0.03" frictionloss="0.01"/>
            <inertial pos="0.0035662 -0.00062307 -0.17246" mass="0.18206"
                      fullinertia="0.0007587 0.0007849 3.9944E-05 7.7195E-07 3.5137E-05 -1.8954E-06"/>
            <geom name="HR_SHANK_collision" pos="0 0 0" quat="1 0 0 0" type="mesh" mesh="hr_shank.STL" class="collision" />
            <geom name="HR_SHANK_visual"    pos="0 0 0" quat="1 0 0 0" material="" type="mesh" mesh="hr_shank.STL" class="visual" />
            <body name="HR_FOOT" pos="0 0 -0.22" quat="1 0 0 0">
              <inertial pos="0 0 0" mass="0.06" diaginertia="1E-12 1E-12 1E-12"/>
              <geom name="HR_FOOT_collision" pos="0 0 0" quat="0.7071067811882787 0.7071067811848163 0 0" type="sphere" size="0.03" class="collision" />
              <geom name="HR_FOOT_visual"    pos="0 0 0" quat="1 0 0 0" material="" type="sphere" size="0.032" class="visual" />
            </body>
          </body>
        </body>
      </body>

      <site name="TORSO_site" pos="0 0 0" quat="1 0 0 0" />
      <camera name="front_camera" mode="track" fovy="90.0"
              quat="4.329780281177467e-17 4.329780281177466e-17 0.7071067811865475 0.7071067811865476"
              pos="0.0 2.0 0.5" />
      <camera name="side_camera" mode="track" fovy="90.0"
              quat="-0.5 -0.4999999999999999 0.5 0.5000000000000001"
              pos="-2.0 0.0 0.5" />
    </body>
  </worldbody>

  <actuator>
    <motor name="FL_HipX_joint_ctrl" joint="FL_HipX_joint" class="motor" gear="1" ctrlrange="-46 46"/>
    <motor name="FL_HipY_joint_ctrl" joint="FL_HipY_joint" class="motor" gear="1" ctrlrange="-46 46"/>
    <motor name="FL_Knee_joint_ctrl" joint="FL_Knee_joint" class="motor" gear="1" ctrlrange="-59 59"/>
    <motor name="FR_HipX_joint_ctrl" joint="FR_HipX_joint" class="motor" gear="1" ctrlrange="-46 46"/>
    <motor name="FR_HipY_joint_ctrl" joint="FR_HipY_joint" class="motor" gear="1" ctrlrange="-46 46"/>
    <motor name="FR_Knee_joint_ctrl" joint="FR_Knee_joint" class="motor" gear="1" ctrlrange="-59 59"/>
    <motor name="HL_HipX_joint_ctrl" joint="HL_HipX_joint" class="motor" gear="1" ctrlrange="-46 46"/>
    <motor name="HL_HipY_joint_ctrl" joint="HL_HipY_joint" class="motor" gear="1" ctrlrange="-46 46"/>
    <motor name="HL_Knee_joint_ctrl" joint="HL_Knee_joint" class="motor" gear="1" ctrlrange="-59 59"/>
    <motor name="HR_HipX_joint_ctrl" joint="HR_HipX_joint" class="motor" gear="1" ctrlrange="-46 46"/>
    <motor name="HR_HipY_joint_ctrl" joint="HR_HipY_joint" class="motor" gear="1" ctrlrange="-46 46"/>
    <motor name="HR_Knee_joint_ctrl" joint="HR_Knee_joint" class="motor" gear="1" ctrlrange="-59 59"/>
  </actuator>

  <contact>
    <exclude body1="TORSO" body2="FL_HIP" />
    <exclude body1="FL_HIP" body2="FL_THIGH" />
    <exclude body1="FL_THIGH" body2="FL_SHANK" />
    <exclude body1="FL_SHANK" body2="FL_FOOT" />
    <exclude body1="TORSO" body2="FR_HIP" />
    <exclude body1="FR_HIP" body2="FR_THIGH" />
    <exclude body1="FR_THIGH" body2="FR_SHANK" />
    <exclude body1="FR_SHANK" body2="FR_FOOT" />
    <exclude body1="TORSO" body2="HL_HIP" />
    <exclude body1="HL_HIP" body2="HL_THIGH" />
    <exclude body1="HL_THIGH" body2="HL_SHANK" />
    <exclude body1="HL_SHANK" body2="HL_FOOT" />
    <exclude body1="TORSO" body2="HR_HIP" />
    <exclude body1="HR_HIP" body2="HR_THIGH" />
    <exclude body1="HR_THIGH" body2="HR_SHANK" />
    <exclude body1="HR_SHANK" body2="HR_FOOT" />
  </contact>

  <sensor>
    <framepos name="TORSO_site_pos" objtype="site" objname="TORSO_site" />
    <framequat name="TORSO_site_quat" objtype="site" objname="TORSO_site" />
    <framelinvel name="TORSO_site_linvel" objtype="site" objname="TORSO_site" />
    <frameangvel name="TORSO_site_angvel" objtype="site" objname="TORSO_site" />
    <velocimeter name="TORSO_site_vel" site="TORSO_site" />
    <accelerometer site="imu_site"/>
    <gyro site="imu_site"/>
  </sensor>
</mujoco>